{
 "cells": [
  {
   "cell_type": "code",
   "execution_count": 6,
   "metadata": {},
   "outputs": [],
   "source": [
    "import pandas as pd\n",
    "import autokeras as ak\n",
    "from tensorflow.keras.models import load_model\n",
    "import tensorflow as tf"
   ]
  },
  {
   "cell_type": "code",
   "execution_count": 7,
   "metadata": {},
   "outputs": [],
   "source": [
    "data_A = pd.read_csv(\"current_csv_files/data_A.csv\", index_col='date_forecast').astype('float')\n",
    "data_B = pd.read_csv(\"current_csv_files/data_B.csv\", index_col='date_forecast').astype('float')\n",
    "data_C = pd.read_csv(\"current_csv_files/data_C.csv\", index_col='date_forecast').astype('float')\n",
    "\n",
    "data_A_train = data_A[data_A['est'] == 0]\n",
    "data_B_train = data_B[data_B['est'] == 0]\n",
    "data_C_train = data_C[data_C['est'] == 0]\n",
    "\n",
    "data_A_val = data_A[data_A['est'] == 1]\n",
    "data_B_val = data_B[data_B['est'] == 1]\n",
    "data_C_val = data_C[data_C['est'] == 1]"
   ]
  },
  {
   "cell_type": "code",
   "execution_count": 8,
   "metadata": {},
   "outputs": [],
   "source": [
    "X_data_A_train = data_A_train\n",
    "y_data_A_train = X_data_A_train.pop('target')\n",
    "\n",
    "X_data_A_val = data_A_val\n",
    "y_data_A_val = X_data_A_val.pop('target')"
   ]
  },
  {
   "cell_type": "code",
   "execution_count": 34,
   "metadata": {},
   "outputs": [
    {
     "name": "stdout",
     "output_type": "stream",
     "text": [
      "Reloading Tuner from ./time_series_forecaster/tuner0.json\n"
     ]
    }
   ],
   "source": [
    "# Initialize the TimeSeriesForecaster\n",
    "reg = ak.TimeseriesForecaster(\n",
    "    lookback=10,  # Lookback can be adjusted based on your time series\n",
    "    predict_from=1,\n",
    "    predict_until=10,\n",
    "    max_trials=10,  # Number of models to try\n",
    "    objective='val_loss',\n",
    "    loss='mean_absolute_error',\n",
    "    metrics=['mean_absolute_error']\n",
    "    \n",
    ")"
   ]
  },
  {
   "cell_type": "code",
   "execution_count": 35,
   "metadata": {},
   "outputs": [
    {
     "name": "stderr",
     "output_type": "stream",
     "text": [
      "WARNING:absl:At this time, the v2.11+ optimizer `tf.keras.optimizers.Adam` runs slowly on M1/M2 Macs, please use the legacy Keras optimizer instead, located at `tf.keras.optimizers.legacy.Adam`.\n"
     ]
    },
    {
     "name": "stdout",
     "output_type": "stream",
     "text": [
      "\n",
      "Search: Running Trial #3\n",
      "\n",
      "Value             |Best Value So Far |Hyperparameter\n",
      "True              |True              |timeseries_block_1/rnn_block_1/bidirectional\n",
      "lstm              |lstm              |timeseries_block_1/rnn_block_1/layer_type\n",
      "2                 |2                 |timeseries_block_1/rnn_block_1/num_layers\n",
      "0.25              |0.5               |regression_head_1/dropout\n",
      "adam              |adam              |optimizer\n",
      "2e-05             |0.001             |learning_rate\n",
      "\n"
     ]
    },
    {
     "name": "stderr",
     "output_type": "stream",
     "text": [
      "WARNING:absl:At this time, the v2.11+ optimizer `tf.keras.optimizers.Adam` runs slowly on M1/M2 Macs, please use the legacy Keras optimizer instead, located at `tf.keras.optimizers.legacy.Adam`.\n"
     ]
    },
    {
     "name": "stdout",
     "output_type": "stream",
     "text": [
      "Epoch 1/10\n",
      "    601/Unknown - 6s 6ms/step - loss: 1024.5109 - mean_absolute_error: 1024.5109"
     ]
    },
    {
     "name": "stderr",
     "output_type": "stream",
     "text": [
      "Traceback (most recent call last):\n",
      "  File \"/Library/Frameworks/Python.framework/Versions/3.11/lib/python3.11/site-packages/keras_tuner/src/engine/base_tuner.py\", line 273, in _try_run_and_update_trial\n",
      "    self._run_and_update_trial(trial, *fit_args, **fit_kwargs)\n",
      "  File \"/Library/Frameworks/Python.framework/Versions/3.11/lib/python3.11/site-packages/keras_tuner/src/engine/base_tuner.py\", line 238, in _run_and_update_trial\n",
      "    results = self.run_trial(trial, *fit_args, **fit_kwargs)\n",
      "              ^^^^^^^^^^^^^^^^^^^^^^^^^^^^^^^^^^^^^^^^^^^^^^\n",
      "  File \"/Library/Frameworks/Python.framework/Versions/3.11/lib/python3.11/site-packages/keras_tuner/src/engine/tuner.py\", line 314, in run_trial\n",
      "    obj_value = self._build_and_fit_model(trial, *args, **copied_kwargs)\n",
      "                ^^^^^^^^^^^^^^^^^^^^^^^^^^^^^^^^^^^^^^^^^^^^^^^^^^^^^^^^\n",
      "  File \"/Library/Frameworks/Python.framework/Versions/3.11/lib/python3.11/site-packages/autokeras/engine/tuner.py\", line 101, in _build_and_fit_model\n",
      "    _, history = utils.fit_with_adaptive_batch_size(\n",
      "                 ^^^^^^^^^^^^^^^^^^^^^^^^^^^^^^^^^^^\n",
      "  File \"/Library/Frameworks/Python.framework/Versions/3.11/lib/python3.11/site-packages/autokeras/utils/utils.py\", line 88, in fit_with_adaptive_batch_size\n",
      "    history = run_with_adaptive_batch_size(\n",
      "              ^^^^^^^^^^^^^^^^^^^^^^^^^^^^^\n",
      "  File \"/Library/Frameworks/Python.framework/Versions/3.11/lib/python3.11/site-packages/autokeras/utils/utils.py\", line 101, in run_with_adaptive_batch_size\n",
      "    history = func(x=x, validation_data=validation_data, **fit_kwargs)\n",
      "              ^^^^^^^^^^^^^^^^^^^^^^^^^^^^^^^^^^^^^^^^^^^^^^^^^^^^^^^^\n",
      "  File \"/Library/Frameworks/Python.framework/Versions/3.11/lib/python3.11/site-packages/autokeras/utils/utils.py\", line 89, in <lambda>\n",
      "    batch_size, lambda **kwargs: model.fit(**kwargs), **fit_kwargs\n",
      "                                 ^^^^^^^^^^^^^^^^^^^\n",
      "  File \"/Library/Frameworks/Python.framework/Versions/3.11/lib/python3.11/site-packages/keras/src/utils/traceback_utils.py\", line 70, in error_handler\n",
      "    raise e.with_traceback(filtered_tb) from None\n",
      "  File \"/Library/Frameworks/Python.framework/Versions/3.11/lib/python3.11/site-packages/tensorflow/python/eager/execute.py\", line 66, in quick_execute\n",
      "    except TypeError as e:\n",
      "tensorflow.python.framework.errors_impl.InvalidArgumentError: Graph execution error:\n",
      "\n",
      "Detected at node mean_absolute_error/sub defined at (most recent call last):\n",
      "  File \"<frozen runpy>\", line 198, in _run_module_as_main\n",
      "\n",
      "  File \"<frozen runpy>\", line 88, in _run_code\n",
      "\n",
      "  File \"/Users/teodorlindell/Library/Python/3.11/lib/python/site-packages/ipykernel_launcher.py\", line 17, in <module>\n",
      "\n",
      "  File \"/Users/teodorlindell/Library/Python/3.11/lib/python/site-packages/traitlets/config/application.py\", line 1043, in launch_instance\n",
      "\n",
      "  File \"/Users/teodorlindell/Library/Python/3.11/lib/python/site-packages/ipykernel/kernelapp.py\", line 725, in start\n",
      "\n",
      "  File \"/Users/teodorlindell/Library/Python/3.11/lib/python/site-packages/tornado/platform/asyncio.py\", line 215, in start\n",
      "\n",
      "  File \"/Library/Frameworks/Python.framework/Versions/3.11/lib/python3.11/asyncio/base_events.py\", line 604, in run_forever\n",
      "\n",
      "  File \"/Library/Frameworks/Python.framework/Versions/3.11/lib/python3.11/asyncio/base_events.py\", line 1909, in _run_once\n",
      "\n",
      "  File \"/Library/Frameworks/Python.framework/Versions/3.11/lib/python3.11/asyncio/events.py\", line 80, in _run\n",
      "\n",
      "  File \"/Users/teodorlindell/Library/Python/3.11/lib/python/site-packages/ipykernel/kernelbase.py\", line 513, in dispatch_queue\n",
      "\n",
      "  File \"/Users/teodorlindell/Library/Python/3.11/lib/python/site-packages/ipykernel/kernelbase.py\", line 502, in process_one\n",
      "\n",
      "  File \"/Users/teodorlindell/Library/Python/3.11/lib/python/site-packages/ipykernel/kernelbase.py\", line 409, in dispatch_shell\n",
      "\n",
      "  File \"/Users/teodorlindell/Library/Python/3.11/lib/python/site-packages/ipykernel/kernelbase.py\", line 729, in execute_request\n",
      "\n",
      "  File \"/Users/teodorlindell/Library/Python/3.11/lib/python/site-packages/ipykernel/ipkernel.py\", line 422, in do_execute\n",
      "\n",
      "  File \"/Users/teodorlindell/Library/Python/3.11/lib/python/site-packages/ipykernel/zmqshell.py\", line 540, in run_cell\n",
      "\n",
      "  File \"/Users/teodorlindell/Library/Python/3.11/lib/python/site-packages/IPython/core/interactiveshell.py\", line 3009, in run_cell\n",
      "\n",
      "  File \"/Users/teodorlindell/Library/Python/3.11/lib/python/site-packages/IPython/core/interactiveshell.py\", line 3064, in _run_cell\n",
      "\n",
      "  File \"/Users/teodorlindell/Library/Python/3.11/lib/python/site-packages/IPython/core/async_helpers.py\", line 129, in _pseudo_sync_runner\n",
      "\n",
      "  File \"/Users/teodorlindell/Library/Python/3.11/lib/python/site-packages/IPython/core/interactiveshell.py\", line 3269, in run_cell_async\n",
      "\n",
      "  File \"/Users/teodorlindell/Library/Python/3.11/lib/python/site-packages/IPython/core/interactiveshell.py\", line 3448, in run_ast_nodes\n",
      "\n",
      "  File \"/Users/teodorlindell/Library/Python/3.11/lib/python/site-packages/IPython/core/interactiveshell.py\", line 3508, in run_code\n",
      "\n",
      "  File \"/var/folders/kq/hk1l39ys077bc7f9741ypg800000gn/T/ipykernel_39453/2508338396.py\", line 2, in <module>\n",
      "\n",
      "  File \"/Library/Frameworks/Python.framework/Versions/3.11/lib/python3.11/site-packages/autokeras/tasks/time_series_forecaster.py\", line 268, in fit\n",
      "\n",
      "  File \"/Library/Frameworks/Python.framework/Versions/3.11/lib/python3.11/site-packages/autokeras/tasks/time_series_forecaster.py\", line 88, in fit\n",
      "\n",
      "  File \"/Library/Frameworks/Python.framework/Versions/3.11/lib/python3.11/site-packages/autokeras/tasks/structured_data.py\", line 139, in fit\n",
      "\n",
      "  File \"/Library/Frameworks/Python.framework/Versions/3.11/lib/python3.11/site-packages/autokeras/auto_model.py\", line 292, in fit\n",
      "\n",
      "  File \"/Library/Frameworks/Python.framework/Versions/3.11/lib/python3.11/site-packages/autokeras/engine/tuner.py\", line 193, in search\n",
      "\n",
      "  File \"/Library/Frameworks/Python.framework/Versions/3.11/lib/python3.11/site-packages/keras_tuner/src/engine/base_tuner.py\", line 233, in search\n",
      "\n",
      "  File \"/Library/Frameworks/Python.framework/Versions/3.11/lib/python3.11/site-packages/keras_tuner/src/engine/base_tuner.py\", line 273, in _try_run_and_update_trial\n",
      "\n",
      "  File \"/Library/Frameworks/Python.framework/Versions/3.11/lib/python3.11/site-packages/keras_tuner/src/engine/base_tuner.py\", line 238, in _run_and_update_trial\n",
      "\n",
      "  File \"/Library/Frameworks/Python.framework/Versions/3.11/lib/python3.11/site-packages/keras_tuner/src/engine/tuner.py\", line 314, in run_trial\n",
      "\n",
      "  File \"/Library/Frameworks/Python.framework/Versions/3.11/lib/python3.11/site-packages/autokeras/engine/tuner.py\", line 101, in _build_and_fit_model\n",
      "\n",
      "  File \"/Library/Frameworks/Python.framework/Versions/3.11/lib/python3.11/site-packages/autokeras/utils/utils.py\", line 88, in fit_with_adaptive_batch_size\n",
      "\n",
      "  File \"/Library/Frameworks/Python.framework/Versions/3.11/lib/python3.11/site-packages/autokeras/utils/utils.py\", line 101, in run_with_adaptive_batch_size\n",
      "\n",
      "  File \"/Library/Frameworks/Python.framework/Versions/3.11/lib/python3.11/site-packages/autokeras/utils/utils.py\", line 89, in <lambda>\n",
      "\n",
      "  File \"/Library/Frameworks/Python.framework/Versions/3.11/lib/python3.11/site-packages/keras/src/utils/traceback_utils.py\", line 65, in error_handler\n",
      "\n",
      "  File \"/Library/Frameworks/Python.framework/Versions/3.11/lib/python3.11/site-packages/keras/src/engine/training.py\", line 1783, in fit\n",
      "\n",
      "  File \"/Library/Frameworks/Python.framework/Versions/3.11/lib/python3.11/site-packages/keras/src/engine/training.py\", line 1377, in train_function\n",
      "\n",
      "  File \"/Library/Frameworks/Python.framework/Versions/3.11/lib/python3.11/site-packages/keras/src/engine/training.py\", line 1360, in step_function\n",
      "\n",
      "  File \"/Library/Frameworks/Python.framework/Versions/3.11/lib/python3.11/site-packages/keras/src/engine/training.py\", line 1349, in run_step\n",
      "\n",
      "  File \"/Library/Frameworks/Python.framework/Versions/3.11/lib/python3.11/site-packages/keras/src/engine/training.py\", line 1127, in train_step\n",
      "\n",
      "  File \"/Library/Frameworks/Python.framework/Versions/3.11/lib/python3.11/site-packages/keras/src/engine/training.py\", line 1185, in compute_loss\n",
      "\n",
      "  File \"/Library/Frameworks/Python.framework/Versions/3.11/lib/python3.11/site-packages/keras/src/engine/compile_utils.py\", line 277, in __call__\n",
      "\n",
      "  File \"/Library/Frameworks/Python.framework/Versions/3.11/lib/python3.11/site-packages/keras/src/losses.py\", line 143, in __call__\n",
      "\n",
      "  File \"/Library/Frameworks/Python.framework/Versions/3.11/lib/python3.11/site-packages/keras/src/losses.py\", line 270, in call\n",
      "\n",
      "  File \"/Library/Frameworks/Python.framework/Versions/3.11/lib/python3.11/site-packages/keras/src/losses.py\", line 1848, in mean_absolute_error\n",
      "\n",
      "Incompatible shapes: [23,1] vs. [24,1]\n",
      "\t [[{{node mean_absolute_error/sub}}]] [Op:__inference_train_function_713297]\n"
     ]
    },
    {
     "ename": "RuntimeError",
     "evalue": "Number of consecutive failures exceeded the limit of 3.\nTraceback (most recent call last):\n  File \"/Library/Frameworks/Python.framework/Versions/3.11/lib/python3.11/site-packages/keras_tuner/src/engine/base_tuner.py\", line 273, in _try_run_and_update_trial\n    self._run_and_update_trial(trial, *fit_args, **fit_kwargs)\n  File \"/Library/Frameworks/Python.framework/Versions/3.11/lib/python3.11/site-packages/keras_tuner/src/engine/base_tuner.py\", line 238, in _run_and_update_trial\n    results = self.run_trial(trial, *fit_args, **fit_kwargs)\n              ^^^^^^^^^^^^^^^^^^^^^^^^^^^^^^^^^^^^^^^^^^^^^^\n  File \"/Library/Frameworks/Python.framework/Versions/3.11/lib/python3.11/site-packages/keras_tuner/src/engine/tuner.py\", line 314, in run_trial\n    obj_value = self._build_and_fit_model(trial, *args, **copied_kwargs)\n                ^^^^^^^^^^^^^^^^^^^^^^^^^^^^^^^^^^^^^^^^^^^^^^^^^^^^^^^^\n  File \"/Library/Frameworks/Python.framework/Versions/3.11/lib/python3.11/site-packages/autokeras/engine/tuner.py\", line 101, in _build_and_fit_model\n    _, history = utils.fit_with_adaptive_batch_size(\n                 ^^^^^^^^^^^^^^^^^^^^^^^^^^^^^^^^^^^\n  File \"/Library/Frameworks/Python.framework/Versions/3.11/lib/python3.11/site-packages/autokeras/utils/utils.py\", line 88, in fit_with_adaptive_batch_size\n    history = run_with_adaptive_batch_size(\n              ^^^^^^^^^^^^^^^^^^^^^^^^^^^^^\n  File \"/Library/Frameworks/Python.framework/Versions/3.11/lib/python3.11/site-packages/autokeras/utils/utils.py\", line 101, in run_with_adaptive_batch_size\n    history = func(x=x, validation_data=validation_data, **fit_kwargs)\n              ^^^^^^^^^^^^^^^^^^^^^^^^^^^^^^^^^^^^^^^^^^^^^^^^^^^^^^^^\n  File \"/Library/Frameworks/Python.framework/Versions/3.11/lib/python3.11/site-packages/autokeras/utils/utils.py\", line 89, in <lambda>\n    batch_size, lambda **kwargs: model.fit(**kwargs), **fit_kwargs\n                                 ^^^^^^^^^^^^^^^^^^^\n  File \"/Library/Frameworks/Python.framework/Versions/3.11/lib/python3.11/site-packages/keras/src/utils/traceback_utils.py\", line 70, in error_handler\n    raise e.with_traceback(filtered_tb) from None\n  File \"/Library/Frameworks/Python.framework/Versions/3.11/lib/python3.11/site-packages/tensorflow/python/eager/execute.py\", line 66, in quick_execute\n    except TypeError as e:\ntensorflow.python.framework.errors_impl.InvalidArgumentError: Graph execution error:\n\nDetected at node mean_absolute_error/sub defined at (most recent call last):\n  File \"<frozen runpy>\", line 198, in _run_module_as_main\n\n  File \"<frozen runpy>\", line 88, in _run_code\n\n  File \"/Users/teodorlindell/Library/Python/3.11/lib/python/site-packages/ipykernel_launcher.py\", line 17, in <module>\n\n  File \"/Users/teodorlindell/Library/Python/3.11/lib/python/site-packages/traitlets/config/application.py\", line 1043, in launch_instance\n\n  File \"/Users/teodorlindell/Library/Python/3.11/lib/python/site-packages/ipykernel/kernelapp.py\", line 725, in start\n\n  File \"/Users/teodorlindell/Library/Python/3.11/lib/python/site-packages/tornado/platform/asyncio.py\", line 215, in start\n\n  File \"/Library/Frameworks/Python.framework/Versions/3.11/lib/python3.11/asyncio/base_events.py\", line 604, in run_forever\n\n  File \"/Library/Frameworks/Python.framework/Versions/3.11/lib/python3.11/asyncio/base_events.py\", line 1909, in _run_once\n\n  File \"/Library/Frameworks/Python.framework/Versions/3.11/lib/python3.11/asyncio/events.py\", line 80, in _run\n\n  File \"/Users/teodorlindell/Library/Python/3.11/lib/python/site-packages/ipykernel/kernelbase.py\", line 513, in dispatch_queue\n\n  File \"/Users/teodorlindell/Library/Python/3.11/lib/python/site-packages/ipykernel/kernelbase.py\", line 502, in process_one\n\n  File \"/Users/teodorlindell/Library/Python/3.11/lib/python/site-packages/ipykernel/kernelbase.py\", line 409, in dispatch_shell\n\n  File \"/Users/teodorlindell/Library/Python/3.11/lib/python/site-packages/ipykernel/kernelbase.py\", line 729, in execute_request\n\n  File \"/Users/teodorlindell/Library/Python/3.11/lib/python/site-packages/ipykernel/ipkernel.py\", line 422, in do_execute\n\n  File \"/Users/teodorlindell/Library/Python/3.11/lib/python/site-packages/ipykernel/zmqshell.py\", line 540, in run_cell\n\n  File \"/Users/teodorlindell/Library/Python/3.11/lib/python/site-packages/IPython/core/interactiveshell.py\", line 3009, in run_cell\n\n  File \"/Users/teodorlindell/Library/Python/3.11/lib/python/site-packages/IPython/core/interactiveshell.py\", line 3064, in _run_cell\n\n  File \"/Users/teodorlindell/Library/Python/3.11/lib/python/site-packages/IPython/core/async_helpers.py\", line 129, in _pseudo_sync_runner\n\n  File \"/Users/teodorlindell/Library/Python/3.11/lib/python/site-packages/IPython/core/interactiveshell.py\", line 3269, in run_cell_async\n\n  File \"/Users/teodorlindell/Library/Python/3.11/lib/python/site-packages/IPython/core/interactiveshell.py\", line 3448, in run_ast_nodes\n\n  File \"/Users/teodorlindell/Library/Python/3.11/lib/python/site-packages/IPython/core/interactiveshell.py\", line 3508, in run_code\n\n  File \"/var/folders/kq/hk1l39ys077bc7f9741ypg800000gn/T/ipykernel_39453/2508338396.py\", line 2, in <module>\n\n  File \"/Library/Frameworks/Python.framework/Versions/3.11/lib/python3.11/site-packages/autokeras/tasks/time_series_forecaster.py\", line 268, in fit\n\n  File \"/Library/Frameworks/Python.framework/Versions/3.11/lib/python3.11/site-packages/autokeras/tasks/time_series_forecaster.py\", line 88, in fit\n\n  File \"/Library/Frameworks/Python.framework/Versions/3.11/lib/python3.11/site-packages/autokeras/tasks/structured_data.py\", line 139, in fit\n\n  File \"/Library/Frameworks/Python.framework/Versions/3.11/lib/python3.11/site-packages/autokeras/auto_model.py\", line 292, in fit\n\n  File \"/Library/Frameworks/Python.framework/Versions/3.11/lib/python3.11/site-packages/autokeras/engine/tuner.py\", line 193, in search\n\n  File \"/Library/Frameworks/Python.framework/Versions/3.11/lib/python3.11/site-packages/keras_tuner/src/engine/base_tuner.py\", line 233, in search\n\n  File \"/Library/Frameworks/Python.framework/Versions/3.11/lib/python3.11/site-packages/keras_tuner/src/engine/base_tuner.py\", line 273, in _try_run_and_update_trial\n\n  File \"/Library/Frameworks/Python.framework/Versions/3.11/lib/python3.11/site-packages/keras_tuner/src/engine/base_tuner.py\", line 238, in _run_and_update_trial\n\n  File \"/Library/Frameworks/Python.framework/Versions/3.11/lib/python3.11/site-packages/keras_tuner/src/engine/tuner.py\", line 314, in run_trial\n\n  File \"/Library/Frameworks/Python.framework/Versions/3.11/lib/python3.11/site-packages/autokeras/engine/tuner.py\", line 101, in _build_and_fit_model\n\n  File \"/Library/Frameworks/Python.framework/Versions/3.11/lib/python3.11/site-packages/autokeras/utils/utils.py\", line 88, in fit_with_adaptive_batch_size\n\n  File \"/Library/Frameworks/Python.framework/Versions/3.11/lib/python3.11/site-packages/autokeras/utils/utils.py\", line 101, in run_with_adaptive_batch_size\n\n  File \"/Library/Frameworks/Python.framework/Versions/3.11/lib/python3.11/site-packages/autokeras/utils/utils.py\", line 89, in <lambda>\n\n  File \"/Library/Frameworks/Python.framework/Versions/3.11/lib/python3.11/site-packages/keras/src/utils/traceback_utils.py\", line 65, in error_handler\n\n  File \"/Library/Frameworks/Python.framework/Versions/3.11/lib/python3.11/site-packages/keras/src/engine/training.py\", line 1783, in fit\n\n  File \"/Library/Frameworks/Python.framework/Versions/3.11/lib/python3.11/site-packages/keras/src/engine/training.py\", line 1377, in train_function\n\n  File \"/Library/Frameworks/Python.framework/Versions/3.11/lib/python3.11/site-packages/keras/src/engine/training.py\", line 1360, in step_function\n\n  File \"/Library/Frameworks/Python.framework/Versions/3.11/lib/python3.11/site-packages/keras/src/engine/training.py\", line 1349, in run_step\n\n  File \"/Library/Frameworks/Python.framework/Versions/3.11/lib/python3.11/site-packages/keras/src/engine/training.py\", line 1127, in train_step\n\n  File \"/Library/Frameworks/Python.framework/Versions/3.11/lib/python3.11/site-packages/keras/src/engine/training.py\", line 1185, in compute_loss\n\n  File \"/Library/Frameworks/Python.framework/Versions/3.11/lib/python3.11/site-packages/keras/src/engine/compile_utils.py\", line 277, in __call__\n\n  File \"/Library/Frameworks/Python.framework/Versions/3.11/lib/python3.11/site-packages/keras/src/losses.py\", line 143, in __call__\n\n  File \"/Library/Frameworks/Python.framework/Versions/3.11/lib/python3.11/site-packages/keras/src/losses.py\", line 270, in call\n\n  File \"/Library/Frameworks/Python.framework/Versions/3.11/lib/python3.11/site-packages/keras/src/losses.py\", line 1848, in mean_absolute_error\n\nIncompatible shapes: [23,1] vs. [24,1]\n\t [[{{node mean_absolute_error/sub}}]] [Op:__inference_train_function_713297]\n",
     "output_type": "error",
     "traceback": [
      "\u001b[0;31m---------------------------------------------------------------------------\u001b[0m",
      "\u001b[0;31mRuntimeError\u001b[0m                              Traceback (most recent call last)",
      "\u001b[1;32m/Users/teodorlindell/Repos/TDT4174-Machine-Learning/teodor/teo_autokerasTS.ipynb Cell 5\u001b[0m line \u001b[0;36m2\n\u001b[1;32m      <a href='vscode-notebook-cell:/Users/teodorlindell/Repos/TDT4174-Machine-Learning/teodor/teo_autokerasTS.ipynb#W6sZmlsZQ%3D%3D?line=0'>1</a>\u001b[0m \u001b[39m# Fit the TimeSeriesForecaster on the training data\u001b[39;00m\n\u001b[0;32m----> <a href='vscode-notebook-cell:/Users/teodorlindell/Repos/TDT4174-Machine-Learning/teodor/teo_autokerasTS.ipynb#W6sZmlsZQ%3D%3D?line=1'>2</a>\u001b[0m reg\u001b[39m.\u001b[39;49mfit(\n\u001b[1;32m      <a href='vscode-notebook-cell:/Users/teodorlindell/Repos/TDT4174-Machine-Learning/teodor/teo_autokerasTS.ipynb#W6sZmlsZQ%3D%3D?line=2'>3</a>\u001b[0m     x\u001b[39m=\u001b[39;49mX_data_A_train,\n\u001b[1;32m      <a href='vscode-notebook-cell:/Users/teodorlindell/Repos/TDT4174-Machine-Learning/teodor/teo_autokerasTS.ipynb#W6sZmlsZQ%3D%3D?line=3'>4</a>\u001b[0m     y\u001b[39m=\u001b[39;49my_data_A_train,\n\u001b[1;32m      <a href='vscode-notebook-cell:/Users/teodorlindell/Repos/TDT4174-Machine-Learning/teodor/teo_autokerasTS.ipynb#W6sZmlsZQ%3D%3D?line=4'>5</a>\u001b[0m     validation_data\u001b[39m=\u001b[39;49m(X_data_A_val, y_data_A_val),\n\u001b[1;32m      <a href='vscode-notebook-cell:/Users/teodorlindell/Repos/TDT4174-Machine-Learning/teodor/teo_autokerasTS.ipynb#W6sZmlsZQ%3D%3D?line=5'>6</a>\u001b[0m     epochs\u001b[39m=\u001b[39;49m\u001b[39m10\u001b[39;49m,\n\u001b[1;32m      <a href='vscode-notebook-cell:/Users/teodorlindell/Repos/TDT4174-Machine-Learning/teodor/teo_autokerasTS.ipynb#W6sZmlsZQ%3D%3D?line=6'>7</a>\u001b[0m )\n",
      "File \u001b[0;32m/Library/Frameworks/Python.framework/Versions/3.11/lib/python3.11/site-packages/autokeras/tasks/time_series_forecaster.py:268\u001b[0m, in \u001b[0;36mTimeseriesForecaster.fit\u001b[0;34m(self, x, y, validation_split, validation_data, **kwargs)\u001b[0m\n\u001b[1;32m    232\u001b[0m \u001b[39mdef\u001b[39;00m \u001b[39mfit\u001b[39m(\n\u001b[1;32m    233\u001b[0m     \u001b[39mself\u001b[39m, x\u001b[39m=\u001b[39m\u001b[39mNone\u001b[39;00m, y\u001b[39m=\u001b[39m\u001b[39mNone\u001b[39;00m, validation_split\u001b[39m=\u001b[39m\u001b[39m0.2\u001b[39m, validation_data\u001b[39m=\u001b[39m\u001b[39mNone\u001b[39;00m, \u001b[39m*\u001b[39m\u001b[39m*\u001b[39mkwargs\n\u001b[1;32m    234\u001b[0m ):\n\u001b[1;32m    235\u001b[0m \u001b[39m    \u001b[39m\u001b[39m\"\"\"Search for the best model and hyperparameters for the AutoModel.\u001b[39;00m\n\u001b[1;32m    236\u001b[0m \n\u001b[1;32m    237\u001b[0m \u001b[39m    # Arguments\u001b[39;00m\n\u001b[0;32m   (...)\u001b[0m\n\u001b[1;32m    266\u001b[0m \u001b[39m            [keras.Model.fit](https://www.tensorflow.org/api_docs/python/tf/keras/Model#fit).\u001b[39;00m\n\u001b[1;32m    267\u001b[0m \u001b[39m    \"\"\"\u001b[39;00m\n\u001b[0;32m--> 268\u001b[0m     \u001b[39msuper\u001b[39;49m()\u001b[39m.\u001b[39;49mfit(\n\u001b[1;32m    269\u001b[0m         x\u001b[39m=\u001b[39;49mx,\n\u001b[1;32m    270\u001b[0m         y\u001b[39m=\u001b[39;49my,\n\u001b[1;32m    271\u001b[0m         validation_split\u001b[39m=\u001b[39;49mvalidation_split,\n\u001b[1;32m    272\u001b[0m         validation_data\u001b[39m=\u001b[39;49mvalidation_data,\n\u001b[1;32m    273\u001b[0m         \u001b[39m*\u001b[39;49m\u001b[39m*\u001b[39;49mkwargs\n\u001b[1;32m    274\u001b[0m     )\n",
      "File \u001b[0;32m/Library/Frameworks/Python.framework/Versions/3.11/lib/python3.11/site-packages/autokeras/tasks/time_series_forecaster.py:88\u001b[0m, in \u001b[0;36mSupervisedTimeseriesDataPipeline.fit\u001b[0;34m(self, x, y, epochs, callbacks, validation_split, validation_data, **kwargs)\u001b[0m\n\u001b[1;32m     85\u001b[0m     y_val \u001b[39m=\u001b[39m y_val[\u001b[39mself\u001b[39m\u001b[39m.\u001b[39mlookback \u001b[39m-\u001b[39m \u001b[39m1\u001b[39m :]\n\u001b[1;32m     86\u001b[0m     validation_data \u001b[39m=\u001b[39m x_val, y_val\n\u001b[0;32m---> 88\u001b[0m history \u001b[39m=\u001b[39m \u001b[39msuper\u001b[39;49m()\u001b[39m.\u001b[39;49mfit(\n\u001b[1;32m     89\u001b[0m     x\u001b[39m=\u001b[39;49mx[: \u001b[39mself\u001b[39;49m\u001b[39m.\u001b[39;49mtrain_len],\n\u001b[1;32m     90\u001b[0m     y\u001b[39m=\u001b[39;49my[\u001b[39mself\u001b[39;49m\u001b[39m.\u001b[39;49mlookback \u001b[39m-\u001b[39;49m \u001b[39m1\u001b[39;49m :],\n\u001b[1;32m     91\u001b[0m     epochs\u001b[39m=\u001b[39;49mepochs,\n\u001b[1;32m     92\u001b[0m     callbacks\u001b[39m=\u001b[39;49mcallbacks,\n\u001b[1;32m     93\u001b[0m     validation_split\u001b[39m=\u001b[39;49mvalidation_split,\n\u001b[1;32m     94\u001b[0m     validation_data\u001b[39m=\u001b[39;49mvalidation_data,\n\u001b[1;32m     95\u001b[0m     \u001b[39m*\u001b[39;49m\u001b[39m*\u001b[39;49mkwargs\n\u001b[1;32m     96\u001b[0m )\n\u001b[1;32m     97\u001b[0m \u001b[39mreturn\u001b[39;00m history\n",
      "File \u001b[0;32m/Library/Frameworks/Python.framework/Versions/3.11/lib/python3.11/site-packages/autokeras/tasks/structured_data.py:139\u001b[0m, in \u001b[0;36mBaseStructuredDataPipeline.fit\u001b[0;34m(self, x, y, epochs, callbacks, validation_split, validation_data, **kwargs)\u001b[0m\n\u001b[1;32m    135\u001b[0m         validation_data \u001b[39m=\u001b[39m \u001b[39mself\u001b[39m\u001b[39m.\u001b[39m_read_from_csv(x_val, y_val)\n\u001b[1;32m    137\u001b[0m \u001b[39mself\u001b[39m\u001b[39m.\u001b[39mcheck_in_fit(x)\n\u001b[0;32m--> 139\u001b[0m history \u001b[39m=\u001b[39m \u001b[39msuper\u001b[39;49m()\u001b[39m.\u001b[39;49mfit(\n\u001b[1;32m    140\u001b[0m     x\u001b[39m=\u001b[39;49mx,\n\u001b[1;32m    141\u001b[0m     y\u001b[39m=\u001b[39;49my,\n\u001b[1;32m    142\u001b[0m     epochs\u001b[39m=\u001b[39;49mepochs,\n\u001b[1;32m    143\u001b[0m     callbacks\u001b[39m=\u001b[39;49mcallbacks,\n\u001b[1;32m    144\u001b[0m     validation_split\u001b[39m=\u001b[39;49mvalidation_split,\n\u001b[1;32m    145\u001b[0m     validation_data\u001b[39m=\u001b[39;49mvalidation_data,\n\u001b[1;32m    146\u001b[0m     \u001b[39m*\u001b[39;49m\u001b[39m*\u001b[39;49mkwargs\n\u001b[1;32m    147\u001b[0m )\n\u001b[1;32m    148\u001b[0m \u001b[39mreturn\u001b[39;00m history\n",
      "File \u001b[0;32m/Library/Frameworks/Python.framework/Versions/3.11/lib/python3.11/site-packages/autokeras/auto_model.py:292\u001b[0m, in \u001b[0;36mAutoModel.fit\u001b[0;34m(self, x, y, batch_size, epochs, callbacks, validation_split, validation_data, verbose, **kwargs)\u001b[0m\n\u001b[1;32m    287\u001b[0m \u001b[39mif\u001b[39;00m validation_data \u001b[39mis\u001b[39;00m \u001b[39mNone\u001b[39;00m \u001b[39mand\u001b[39;00m validation_split:\n\u001b[1;32m    288\u001b[0m     dataset, validation_data \u001b[39m=\u001b[39m data_utils\u001b[39m.\u001b[39msplit_dataset(\n\u001b[1;32m    289\u001b[0m         dataset, validation_split\n\u001b[1;32m    290\u001b[0m     )\n\u001b[0;32m--> 292\u001b[0m history \u001b[39m=\u001b[39m \u001b[39mself\u001b[39;49m\u001b[39m.\u001b[39;49mtuner\u001b[39m.\u001b[39;49msearch(\n\u001b[1;32m    293\u001b[0m     x\u001b[39m=\u001b[39;49mdataset,\n\u001b[1;32m    294\u001b[0m     epochs\u001b[39m=\u001b[39;49mepochs,\n\u001b[1;32m    295\u001b[0m     callbacks\u001b[39m=\u001b[39;49mcallbacks,\n\u001b[1;32m    296\u001b[0m     validation_data\u001b[39m=\u001b[39;49mvalidation_data,\n\u001b[1;32m    297\u001b[0m     validation_split\u001b[39m=\u001b[39;49mvalidation_split,\n\u001b[1;32m    298\u001b[0m     verbose\u001b[39m=\u001b[39;49mverbose,\n\u001b[1;32m    299\u001b[0m     \u001b[39m*\u001b[39;49m\u001b[39m*\u001b[39;49mkwargs\n\u001b[1;32m    300\u001b[0m )\n\u001b[1;32m    302\u001b[0m \u001b[39mreturn\u001b[39;00m history\n",
      "File \u001b[0;32m/Library/Frameworks/Python.framework/Versions/3.11/lib/python3.11/site-packages/autokeras/engine/tuner.py:193\u001b[0m, in \u001b[0;36mAutoTuner.search\u001b[0;34m(self, epochs, callbacks, validation_split, verbose, **fit_kwargs)\u001b[0m\n\u001b[1;32m    191\u001b[0m \u001b[39mself\u001b[39m\u001b[39m.\u001b[39m_try_build(hp)\n\u001b[1;32m    192\u001b[0m \u001b[39mself\u001b[39m\u001b[39m.\u001b[39moracle\u001b[39m.\u001b[39mupdate_space(hp)\n\u001b[0;32m--> 193\u001b[0m \u001b[39msuper\u001b[39;49m()\u001b[39m.\u001b[39;49msearch(\n\u001b[1;32m    194\u001b[0m     epochs\u001b[39m=\u001b[39;49mepochs, callbacks\u001b[39m=\u001b[39;49mnew_callbacks, verbose\u001b[39m=\u001b[39;49mverbose, \u001b[39m*\u001b[39;49m\u001b[39m*\u001b[39;49mfit_kwargs\n\u001b[1;32m    195\u001b[0m )\n\u001b[1;32m    197\u001b[0m \u001b[39m# Train the best model use validation data.\u001b[39;00m\n\u001b[1;32m    198\u001b[0m \u001b[39m# Train the best model with enough number of epochs.\u001b[39;00m\n\u001b[1;32m    199\u001b[0m \u001b[39mif\u001b[39;00m validation_split \u001b[39m>\u001b[39m \u001b[39m0\u001b[39m \u001b[39mor\u001b[39;00m early_stopping_inserted:\n",
      "File \u001b[0;32m/Library/Frameworks/Python.framework/Versions/3.11/lib/python3.11/site-packages/keras_tuner/src/engine/base_tuner.py:234\u001b[0m, in \u001b[0;36mBaseTuner.search\u001b[0;34m(self, *fit_args, **fit_kwargs)\u001b[0m\n\u001b[1;32m    232\u001b[0m     \u001b[39mself\u001b[39m\u001b[39m.\u001b[39mon_trial_begin(trial)\n\u001b[1;32m    233\u001b[0m     \u001b[39mself\u001b[39m\u001b[39m.\u001b[39m_try_run_and_update_trial(trial, \u001b[39m*\u001b[39mfit_args, \u001b[39m*\u001b[39m\u001b[39m*\u001b[39mfit_kwargs)\n\u001b[0;32m--> 234\u001b[0m     \u001b[39mself\u001b[39;49m\u001b[39m.\u001b[39;49mon_trial_end(trial)\n\u001b[1;32m    235\u001b[0m \u001b[39mself\u001b[39m\u001b[39m.\u001b[39mon_search_end()\n",
      "File \u001b[0;32m/Library/Frameworks/Python.framework/Versions/3.11/lib/python3.11/site-packages/keras_tuner/src/engine/base_tuner.py:338\u001b[0m, in \u001b[0;36mBaseTuner.on_trial_end\u001b[0;34m(self, trial)\u001b[0m\n\u001b[1;32m    332\u001b[0m \u001b[39mdef\u001b[39;00m \u001b[39mon_trial_end\u001b[39m(\u001b[39mself\u001b[39m, trial):\n\u001b[1;32m    333\u001b[0m \u001b[39m    \u001b[39m\u001b[39m\"\"\"Called at the end of a trial.\u001b[39;00m\n\u001b[1;32m    334\u001b[0m \n\u001b[1;32m    335\u001b[0m \u001b[39m    Args:\u001b[39;00m\n\u001b[1;32m    336\u001b[0m \u001b[39m        trial: A `Trial` instance.\u001b[39;00m\n\u001b[1;32m    337\u001b[0m \u001b[39m    \"\"\"\u001b[39;00m\n\u001b[0;32m--> 338\u001b[0m     \u001b[39mself\u001b[39;49m\u001b[39m.\u001b[39;49moracle\u001b[39m.\u001b[39;49mend_trial(trial)\n\u001b[1;32m    339\u001b[0m     \u001b[39mself\u001b[39m\u001b[39m.\u001b[39msave()\n",
      "File \u001b[0;32m/Library/Frameworks/Python.framework/Versions/3.11/lib/python3.11/site-packages/keras_tuner/src/engine/oracle.py:108\u001b[0m, in \u001b[0;36msynchronized.<locals>.wrapped_func\u001b[0;34m(*args, **kwargs)\u001b[0m\n\u001b[1;32m    106\u001b[0m     LOCKS[oracle]\u001b[39m.\u001b[39macquire()\n\u001b[1;32m    107\u001b[0m     THREADS[oracle] \u001b[39m=\u001b[39m thread_name\n\u001b[0;32m--> 108\u001b[0m ret_val \u001b[39m=\u001b[39m func(\u001b[39m*\u001b[39;49margs, \u001b[39m*\u001b[39;49m\u001b[39m*\u001b[39;49mkwargs)\n\u001b[1;32m    109\u001b[0m \u001b[39mif\u001b[39;00m need_acquire:\n\u001b[1;32m    110\u001b[0m     THREADS[oracle] \u001b[39m=\u001b[39m \u001b[39mNone\u001b[39;00m\n",
      "File \u001b[0;32m/Library/Frameworks/Python.framework/Versions/3.11/lib/python3.11/site-packages/keras_tuner/src/engine/oracle.py:577\u001b[0m, in \u001b[0;36mOracle.end_trial\u001b[0;34m(self, trial)\u001b[0m\n\u001b[1;32m    575\u001b[0m \u001b[39mif\u001b[39;00m \u001b[39mnot\u001b[39;00m \u001b[39mself\u001b[39m\u001b[39m.\u001b[39m_retry(trial):\n\u001b[1;32m    576\u001b[0m     \u001b[39mself\u001b[39m\u001b[39m.\u001b[39mend_order\u001b[39m.\u001b[39mappend(trial\u001b[39m.\u001b[39mtrial_id)\n\u001b[0;32m--> 577\u001b[0m     \u001b[39mself\u001b[39;49m\u001b[39m.\u001b[39;49m_check_consecutive_failures()\n\u001b[1;32m    579\u001b[0m \u001b[39mself\u001b[39m\u001b[39m.\u001b[39m_save_trial(trial)\n\u001b[1;32m    580\u001b[0m \u001b[39mself\u001b[39m\u001b[39m.\u001b[39msave()\n",
      "File \u001b[0;32m/Library/Frameworks/Python.framework/Versions/3.11/lib/python3.11/site-packages/keras_tuner/src/engine/oracle.py:534\u001b[0m, in \u001b[0;36mOracle._check_consecutive_failures\u001b[0;34m(self)\u001b[0m\n\u001b[1;32m    532\u001b[0m     consecutive_failures \u001b[39m=\u001b[39m \u001b[39m0\u001b[39m\n\u001b[1;32m    533\u001b[0m \u001b[39mif\u001b[39;00m consecutive_failures \u001b[39m==\u001b[39m \u001b[39mself\u001b[39m\u001b[39m.\u001b[39mmax_consecutive_failed_trials:\n\u001b[0;32m--> 534\u001b[0m     \u001b[39mraise\u001b[39;00m \u001b[39mRuntimeError\u001b[39;00m(\n\u001b[1;32m    535\u001b[0m         \u001b[39m\"\u001b[39m\u001b[39mNumber of consecutive failures exceeded the limit \u001b[39m\u001b[39m\"\u001b[39m\n\u001b[1;32m    536\u001b[0m         \u001b[39mf\u001b[39m\u001b[39m\"\u001b[39m\u001b[39mof \u001b[39m\u001b[39m{\u001b[39;00m\u001b[39mself\u001b[39m\u001b[39m.\u001b[39mmax_consecutive_failed_trials\u001b[39m}\u001b[39;00m\u001b[39m.\u001b[39m\u001b[39m\\n\u001b[39;00m\u001b[39m\"\u001b[39m\n\u001b[1;32m    537\u001b[0m         \u001b[39m+\u001b[39m (trial\u001b[39m.\u001b[39mmessage \u001b[39mor\u001b[39;00m \u001b[39m\"\u001b[39m\u001b[39m\"\u001b[39m)\n\u001b[1;32m    538\u001b[0m     )\n",
      "\u001b[0;31mRuntimeError\u001b[0m: Number of consecutive failures exceeded the limit of 3.\nTraceback (most recent call last):\n  File \"/Library/Frameworks/Python.framework/Versions/3.11/lib/python3.11/site-packages/keras_tuner/src/engine/base_tuner.py\", line 273, in _try_run_and_update_trial\n    self._run_and_update_trial(trial, *fit_args, **fit_kwargs)\n  File \"/Library/Frameworks/Python.framework/Versions/3.11/lib/python3.11/site-packages/keras_tuner/src/engine/base_tuner.py\", line 238, in _run_and_update_trial\n    results = self.run_trial(trial, *fit_args, **fit_kwargs)\n              ^^^^^^^^^^^^^^^^^^^^^^^^^^^^^^^^^^^^^^^^^^^^^^\n  File \"/Library/Frameworks/Python.framework/Versions/3.11/lib/python3.11/site-packages/keras_tuner/src/engine/tuner.py\", line 314, in run_trial\n    obj_value = self._build_and_fit_model(trial, *args, **copied_kwargs)\n                ^^^^^^^^^^^^^^^^^^^^^^^^^^^^^^^^^^^^^^^^^^^^^^^^^^^^^^^^\n  File \"/Library/Frameworks/Python.framework/Versions/3.11/lib/python3.11/site-packages/autokeras/engine/tuner.py\", line 101, in _build_and_fit_model\n    _, history = utils.fit_with_adaptive_batch_size(\n                 ^^^^^^^^^^^^^^^^^^^^^^^^^^^^^^^^^^^\n  File \"/Library/Frameworks/Python.framework/Versions/3.11/lib/python3.11/site-packages/autokeras/utils/utils.py\", line 88, in fit_with_adaptive_batch_size\n    history = run_with_adaptive_batch_size(\n              ^^^^^^^^^^^^^^^^^^^^^^^^^^^^^\n  File \"/Library/Frameworks/Python.framework/Versions/3.11/lib/python3.11/site-packages/autokeras/utils/utils.py\", line 101, in run_with_adaptive_batch_size\n    history = func(x=x, validation_data=validation_data, **fit_kwargs)\n              ^^^^^^^^^^^^^^^^^^^^^^^^^^^^^^^^^^^^^^^^^^^^^^^^^^^^^^^^\n  File \"/Library/Frameworks/Python.framework/Versions/3.11/lib/python3.11/site-packages/autokeras/utils/utils.py\", line 89, in <lambda>\n    batch_size, lambda **kwargs: model.fit(**kwargs), **fit_kwargs\n                                 ^^^^^^^^^^^^^^^^^^^\n  File \"/Library/Frameworks/Python.framework/Versions/3.11/lib/python3.11/site-packages/keras/src/utils/traceback_utils.py\", line 70, in error_handler\n    raise e.with_traceback(filtered_tb) from None\n  File \"/Library/Frameworks/Python.framework/Versions/3.11/lib/python3.11/site-packages/tensorflow/python/eager/execute.py\", line 66, in quick_execute\n    except TypeError as e:\ntensorflow.python.framework.errors_impl.InvalidArgumentError: Graph execution error:\n\nDetected at node mean_absolute_error/sub defined at (most recent call last):\n  File \"<frozen runpy>\", line 198, in _run_module_as_main\n\n  File \"<frozen runpy>\", line 88, in _run_code\n\n  File \"/Users/teodorlindell/Library/Python/3.11/lib/python/site-packages/ipykernel_launcher.py\", line 17, in <module>\n\n  File \"/Users/teodorlindell/Library/Python/3.11/lib/python/site-packages/traitlets/config/application.py\", line 1043, in launch_instance\n\n  File \"/Users/teodorlindell/Library/Python/3.11/lib/python/site-packages/ipykernel/kernelapp.py\", line 725, in start\n\n  File \"/Users/teodorlindell/Library/Python/3.11/lib/python/site-packages/tornado/platform/asyncio.py\", line 215, in start\n\n  File \"/Library/Frameworks/Python.framework/Versions/3.11/lib/python3.11/asyncio/base_events.py\", line 604, in run_forever\n\n  File \"/Library/Frameworks/Python.framework/Versions/3.11/lib/python3.11/asyncio/base_events.py\", line 1909, in _run_once\n\n  File \"/Library/Frameworks/Python.framework/Versions/3.11/lib/python3.11/asyncio/events.py\", line 80, in _run\n\n  File \"/Users/teodorlindell/Library/Python/3.11/lib/python/site-packages/ipykernel/kernelbase.py\", line 513, in dispatch_queue\n\n  File \"/Users/teodorlindell/Library/Python/3.11/lib/python/site-packages/ipykernel/kernelbase.py\", line 502, in process_one\n\n  File \"/Users/teodorlindell/Library/Python/3.11/lib/python/site-packages/ipykernel/kernelbase.py\", line 409, in dispatch_shell\n\n  File \"/Users/teodorlindell/Library/Python/3.11/lib/python/site-packages/ipykernel/kernelbase.py\", line 729, in execute_request\n\n  File \"/Users/teodorlindell/Library/Python/3.11/lib/python/site-packages/ipykernel/ipkernel.py\", line 422, in do_execute\n\n  File \"/Users/teodorlindell/Library/Python/3.11/lib/python/site-packages/ipykernel/zmqshell.py\", line 540, in run_cell\n\n  File \"/Users/teodorlindell/Library/Python/3.11/lib/python/site-packages/IPython/core/interactiveshell.py\", line 3009, in run_cell\n\n  File \"/Users/teodorlindell/Library/Python/3.11/lib/python/site-packages/IPython/core/interactiveshell.py\", line 3064, in _run_cell\n\n  File \"/Users/teodorlindell/Library/Python/3.11/lib/python/site-packages/IPython/core/async_helpers.py\", line 129, in _pseudo_sync_runner\n\n  File \"/Users/teodorlindell/Library/Python/3.11/lib/python/site-packages/IPython/core/interactiveshell.py\", line 3269, in run_cell_async\n\n  File \"/Users/teodorlindell/Library/Python/3.11/lib/python/site-packages/IPython/core/interactiveshell.py\", line 3448, in run_ast_nodes\n\n  File \"/Users/teodorlindell/Library/Python/3.11/lib/python/site-packages/IPython/core/interactiveshell.py\", line 3508, in run_code\n\n  File \"/var/folders/kq/hk1l39ys077bc7f9741ypg800000gn/T/ipykernel_39453/2508338396.py\", line 2, in <module>\n\n  File \"/Library/Frameworks/Python.framework/Versions/3.11/lib/python3.11/site-packages/autokeras/tasks/time_series_forecaster.py\", line 268, in fit\n\n  File \"/Library/Frameworks/Python.framework/Versions/3.11/lib/python3.11/site-packages/autokeras/tasks/time_series_forecaster.py\", line 88, in fit\n\n  File \"/Library/Frameworks/Python.framework/Versions/3.11/lib/python3.11/site-packages/autokeras/tasks/structured_data.py\", line 139, in fit\n\n  File \"/Library/Frameworks/Python.framework/Versions/3.11/lib/python3.11/site-packages/autokeras/auto_model.py\", line 292, in fit\n\n  File \"/Library/Frameworks/Python.framework/Versions/3.11/lib/python3.11/site-packages/autokeras/engine/tuner.py\", line 193, in search\n\n  File \"/Library/Frameworks/Python.framework/Versions/3.11/lib/python3.11/site-packages/keras_tuner/src/engine/base_tuner.py\", line 233, in search\n\n  File \"/Library/Frameworks/Python.framework/Versions/3.11/lib/python3.11/site-packages/keras_tuner/src/engine/base_tuner.py\", line 273, in _try_run_and_update_trial\n\n  File \"/Library/Frameworks/Python.framework/Versions/3.11/lib/python3.11/site-packages/keras_tuner/src/engine/base_tuner.py\", line 238, in _run_and_update_trial\n\n  File \"/Library/Frameworks/Python.framework/Versions/3.11/lib/python3.11/site-packages/keras_tuner/src/engine/tuner.py\", line 314, in run_trial\n\n  File \"/Library/Frameworks/Python.framework/Versions/3.11/lib/python3.11/site-packages/autokeras/engine/tuner.py\", line 101, in _build_and_fit_model\n\n  File \"/Library/Frameworks/Python.framework/Versions/3.11/lib/python3.11/site-packages/autokeras/utils/utils.py\", line 88, in fit_with_adaptive_batch_size\n\n  File \"/Library/Frameworks/Python.framework/Versions/3.11/lib/python3.11/site-packages/autokeras/utils/utils.py\", line 101, in run_with_adaptive_batch_size\n\n  File \"/Library/Frameworks/Python.framework/Versions/3.11/lib/python3.11/site-packages/autokeras/utils/utils.py\", line 89, in <lambda>\n\n  File \"/Library/Frameworks/Python.framework/Versions/3.11/lib/python3.11/site-packages/keras/src/utils/traceback_utils.py\", line 65, in error_handler\n\n  File \"/Library/Frameworks/Python.framework/Versions/3.11/lib/python3.11/site-packages/keras/src/engine/training.py\", line 1783, in fit\n\n  File \"/Library/Frameworks/Python.framework/Versions/3.11/lib/python3.11/site-packages/keras/src/engine/training.py\", line 1377, in train_function\n\n  File \"/Library/Frameworks/Python.framework/Versions/3.11/lib/python3.11/site-packages/keras/src/engine/training.py\", line 1360, in step_function\n\n  File \"/Library/Frameworks/Python.framework/Versions/3.11/lib/python3.11/site-packages/keras/src/engine/training.py\", line 1349, in run_step\n\n  File \"/Library/Frameworks/Python.framework/Versions/3.11/lib/python3.11/site-packages/keras/src/engine/training.py\", line 1127, in train_step\n\n  File \"/Library/Frameworks/Python.framework/Versions/3.11/lib/python3.11/site-packages/keras/src/engine/training.py\", line 1185, in compute_loss\n\n  File \"/Library/Frameworks/Python.framework/Versions/3.11/lib/python3.11/site-packages/keras/src/engine/compile_utils.py\", line 277, in __call__\n\n  File \"/Library/Frameworks/Python.framework/Versions/3.11/lib/python3.11/site-packages/keras/src/losses.py\", line 143, in __call__\n\n  File \"/Library/Frameworks/Python.framework/Versions/3.11/lib/python3.11/site-packages/keras/src/losses.py\", line 270, in call\n\n  File \"/Library/Frameworks/Python.framework/Versions/3.11/lib/python3.11/site-packages/keras/src/losses.py\", line 1848, in mean_absolute_error\n\nIncompatible shapes: [23,1] vs. [24,1]\n\t [[{{node mean_absolute_error/sub}}]] [Op:__inference_train_function_713297]\n"
     ]
    }
   ],
   "source": [
    "# Fit the TimeSeriesForecaster on the training data\n",
    "reg.fit(\n",
    "    x=X_data_A_train,\n",
    "    y=y_data_A_train,\n",
    "    validation_data=(X_data_A_val, y_data_A_val),\n",
    "    epochs=10,\n",
    ")"
   ]
  },
  {
   "cell_type": "code",
   "execution_count": 31,
   "metadata": {},
   "outputs": [
    {
     "data": {
      "text/plain": [
       "(19553, 19553, 1930, 1930)"
      ]
     },
     "execution_count": 31,
     "metadata": {},
     "output_type": "execute_result"
    }
   ],
   "source": [
    "len(X_data_A_train), y_data_A_train.size, len(X_data_A_val), y_data_A_val.size"
   ]
  },
  {
   "cell_type": "code",
   "execution_count": 27,
   "metadata": {},
   "outputs": [
    {
     "data": {
      "text/plain": [
       "83.91304347826087"
      ]
     },
     "execution_count": 27,
     "metadata": {},
     "output_type": "execute_result"
    }
   ],
   "source": [
    "1930 / 23"
   ]
  },
  {
   "cell_type": "code",
   "execution_count": null,
   "metadata": {},
   "outputs": [],
   "source": [
    "# Predict with the best model\n",
    "predicted_y = reg.predict(x_test)\n",
    "\n",
    "# Evaluate the best model with testing data\n",
    "eval_result = reg.evaluate(x_test, y_test)\n",
    "\n",
    "# Get the model\n",
    "model = reg.export_model()\n",
    "\n",
    "# Save the model\n",
    "model.save('best_autokeras_model.h5')\n",
    "\n",
    "# Load the model\n",
    "loaded_model = load_model('best_autokeras_model.h5', custom_objects=ak.CUSTOM_OBJECTS)\n",
    "\n",
    "# Use the loaded model to predict\n",
    "predicted_y = loaded_model.predict(x_test)\n",
    "\n",
    "print('Evaluation results:', eval_result)"
   ]
  }
 ],
 "metadata": {
  "kernelspec": {
   "display_name": "Python 3",
   "language": "python",
   "name": "python3"
  },
  "language_info": {
   "codemirror_mode": {
    "name": "ipython",
    "version": 3
   },
   "file_extension": ".py",
   "mimetype": "text/x-python",
   "name": "python",
   "nbconvert_exporter": "python",
   "pygments_lexer": "ipython3",
   "version": "3.11.0"
  }
 },
 "nbformat": 4,
 "nbformat_minor": 2
}
